Workbook

Sheet Итог
A1: Сверка ETM ↔ 1С ↔ реестр: итог
A2: Числа в первом блоке — формулы по листам отчёта.
A4: Субагентов в сверке | B4: =COUNTA('По субагентам'!A5:A104)
A5: Суммарный разрыв (сальдо 1С + баланс ETM) на конец периода, KGS | B5: ='По субагентам'!C105
A6: Рекомендуется сдвинуть баланс ETM (нетто), KGS | B6: ='По субагентам'!D105
A7: Рекомендуется исправить в 1С (нетто), KGS | B7: ='По субагентам'!E105
A8: Нужно выяснить (нетто), KGS | B8: ='По субагентам'!F105
A9: Остаток разрыва после правок (=выяснить + округления), KGS | B9: ='По субагентам'!K105
A10: Не объяснено мостом: сумма по 100 субагентам, KGS | B10: =SUM('Мост'!W4:W103)
A12: Что нашли (факты по данным)
A13: Сумма модулей: сдвиг баланса ETM по субагентам, KGS | B13: 55163943
A14: Сумма модулей: правки в 1С по субагентам, KGS | B14: 12258753
A15: Сумма модулей: «сначала выяснить» по субагентам, KGS | B15: 38343106
A16: Операций ETM / строк 1С (последние версии актов) / строк реестра | B16: 25,237 / 18,711 / 12,146
A17: Групп билетов (заказов) всего | B17: 15499
A18: Групп, присутствующих и в ETM, и в 1С | B18: 13585
A19: …из них сошлись до 5 KGS | B19: 94.1%
A20: Группы с неверной суммой | B20: 758
A21: …подтверждено реестром как ошибка 1С (A) | B21: 195
A22: …подтверждено реестром как ошибка бота (A) | B22: 200
A23: …похоже на опечатку цифр в 1С (гипотеза, B) | B23: 29
A24: …источник не установить без бухгалтера (C) | B24: 334
A25: Двойных списаний бота | B25: 40
A26: Продажи реестра и 1С, которые бот не перенёс в ETM | B26: 83
A27: Операции ETM без реализации в 1С (акт за месяц есть) | B27: 243
A28: Операции ETM, где акт 1С за месяц не выгружен | B28: 487
A29: Поступления 1С без оплаты в ETM | B29: 221
A30: …их сумма, KGS (главный по величине источник разрыва) | B30: 60646400
A31: Повторные зачисления оплат в ETM | B31: 25
... A38: Разрывов цепочки баланса ETM (по субагенту; одинаковая секунда) | B38: 6
A40: Честные оговорки
A41: • Это кандидаты с источником и уверенностью, а не «N ошибок»: A — подтверждено вторым источником, B — гипотеза, C — данных недостаточно.
A42: • Источник нельзя установить для 334 расхождений в сумме: у билетов, выписанных самим субагентом, нет записи в реестре — третьего голоса нет.
A43: • Мост построен без заплаток: каждая строка 1С и ETM попала ровно в одну колонку, «не объяснено» — формула и равна нулю; но колонки «выяснить» (начальный разрыв, недостающие акты) — честно нераспределённые суммы.
A44: • Итоги «нетто» скрывают взаимное погашение разных знаков — рядом показаны суммы модулей по субагентам.
A45: • ETM balance_after — сквозной баланс субагента, а не договора: цепочка проверяется по субагенту.
A46: • ML размечен правилами (слабая разметка) и работает как приоритизатор; его качество показано рядом с baseline и скромное.

Sheet По субагентам
A1: Отчёт по каждому субагенту: что двигать, что исправлять, что выяснить
A2: Разрыв = сальдо 1С + баланс ETM (идеал 0). Корректировки закрывают найденные расхождения; то, что данные объяснить не могут, вынесено в «Выяснить», а не растворено в остатке.
A4: Субагент | B4: Разрыв на начало периода | C4: Разрыв на конец (сальдо 1С + баланс ETM) | D4: Сдвинуть баланс ETM на, KGS | E4: Исправить в 1С на, KGS | F4: Сначала выяснить, KGS | G4: Округления групп, KGS | H4: Рекомендация | I4: Проблемных групп и платежей | J4: Месяцев без акта 1С | K4: Остаток после правок, KGS (=C+D+E) | L4: Проверка: остаток − выяснить − округление − необъяснённое (≈0)
A5: SkyWay Travel | B5: 0 | C5: -8740000 | D5: 7406401.6 | E5: 1306266.3 | F5: -27327.17 | G5: -4.91 | H5: Сдвинуть баланс ETM на +7,406,401.59 (дубль списания: 6; бот не перенёс продажу: 8; повторная оплата: 1; оплата не зачислена: 22); Исправить 1С на +1,306,266.33 (не выставлено в 1С: 29); Сначала выяснить -27,327.17 (начальный разрыв, недостающие акты, спорные суммы) | I5: 156 | J5: 0 | K5: =C5+D5+E5 | L5: =ROUND(K5-F5-G5-(-0.000000002),2)
A6: ИП Токтосун кызы Н. | B6: 3674160.7 | C6: 2741200.5 | D6: 967849.87 | E6: -109475.16 | F6: 3599573.9 | G6: 1.3 | H6: Сдвинуть баланс ETM на +967,849.87 (дубль списания: 1; оплата не зачислена: 4); Исправить 1С на -109,475.16 (не выставлено в 1С: 1; оплата не проведена: 1); Сначала выяснить +3,599,573.86 (начальный разрыв, недостающие акты, спорные суммы) | I6: 47 | J6: 1 | K6: =C6+D6+E6 | L6: =ROUND(K6-F6-G6-(0.000000001),2)
A7: Джолдош уулу Руслан | B7: -3723651.6 | C7: -4467449.9 | D7: 733276.9 | E7: 10000 | F7: -3724173 | G7: 0 | H7: Сдвинуть баланс ETM на +733,276.90 (дубль списания: 1; оплата не зачислена: 1); Исправить 1С на +10,000.00; Сначала выяснить -3,724,172.96 (начальный разрыв, недостающие акты, спорные суммы) | I7: 5 | J7: 0 | K7: =C7+D7+E7 | L7: =ROUND(K7-F7-G7-(-0.000000001),2)
A8: Steppe Travel | B8: 3309463.7 | C8: 2374699.1 | D8: 820246.08 | E8: 114481.21 | F8: 3309426.4 | G8: -7.2759576e-12 | H8: Сдвинуть баланс ETM на +820,246.08 (дубль списания: 1; бот не перенёс продажу: 1; оплата не зачислена: 2); Исправить 1С на +114,481.21 (не выставлено в 1С: 3); Сначала выяснить +3,309,426.35 (начальный разрыв, недостающие акты, спорные суммы) | I8: 10 | J8: 0 | K8: =C8+D8+E8 | L8: =ROUND(K8-F8-G8-(0.000000000),2)
A9: ОсОО Ала-Арча Авиа | B9: 3582785.7 | C9: 3072665.4 | D9: 424333.4 | E9: 88040.15 | F9: 3585038.9 | G9: 2.910383e-11 | H9: Сдвинуть баланс ETM на +424,333.40 (бот не перенёс продажу: 1; оплата не зачислена: 2); Исправить 1С на +88,040.15 (не выставлено в 1С: 2); Сначала выяснить +3,585,038.94 (начальный разрыв, недостающие акты, спорные суммы) | I9: 9 | J9: 0 | K9: =C9+D9+E9 | L9: =ROUND(K9-F9-G9-(0.000000000),2)
A10: Karakol Express | B10: 23846.3 | C10: -3899769.5 | D10: 3573418.1 | E10: 376207.84 | F10: 49861.13 | G10: -4.65 | H10: Сдвинуть баланс ETM на +3,573,418.13 (дубль списания: 2; бот не перенёс продажу: 6; повторная оплата: 3; оплата не зачислена: 21); Исправить 1С на +376,207.84 (не выставлено в 1С: 19); Сначала выяснить +49,861.13 (начальный разрыв, недостающие акты, спорные суммы) | I10: 112 | J10: 0 | K10: =C10+D10+E10 | L10: =ROUND(K10-F10-G10-(0.000000000),2)
A11: ОсОО Тянь-Шань Вояж | B11: -3914150.6 | C11: -3913364.4 | D11: 18213.79 | E11: -19000 | F11: -3914150.6 | G11: 7.2759576e-12 | H11: Сдвинуть баланс ETM на +18,213.79; Исправить 1С на -19,000.00; Сначала выяснить -3,914,150.59 (начальный разрыв, недостающие акты, спорные суммы) | I11: 4 | J11: 0 | K11: =C11+D11+E11 | L11: =ROUND(K11-F11-G11-(0.000000000),2)
A12: Ala-Too Travel | B12: -3233430.5 | C12: -3317307.5 | D12: 0 | E12: 83859.22 | F12: -3233448.3 | G12: -1.4551915e-11 | H12: Исправить 1С на +83,859.22 (не выставлено в 1С: 2); Сначала выяснить -3,233,448.31 (начальный разрыв, недостающие акты, спорные суммы) | I12: 4 | J12: 0 | K12: =C12+D12+E12 | L12: =ROUND(K12-F12-G12-(0.000000000),2)
A13: МУРАС ТРИП | B13: -2130878.8 | C13: -3218410.2 | D13: 919294.65 | E13: 158484.24 | F13: -2140631.3 | G13: 1.4551915e-11 | H13: Сдвинуть баланс ETM на +919,294.65 (дубль списания: 1; оплата не зачислена: 4); Исправить 1С на +158,484.24 (не выставлено в 1С: 1); Сначала выяснить -2,140,631.32 (начальный разрыв, недостающие акты, спорные суммы) | I13: 30 | J13: 1 | K13: =C13+D13+E13 | L13: =ROUND(K13-F13-G13-(0.000000000),2)
A14: Сатар уулу Санжар | B14: 3273224.4 | C14: 1019008 | D14: 1068778.6 | E14: -184864.77 | F14: 1902926.2 | G14: -4.4 | H14: Сдвинуть баланс ETM на +1,068,778.64 (дубль списания: 1; бот не перенёс продажу: 2; повторная оплата: 1; оплата не зачислена: 7; оплата не тому субагенту: 1); Исправить 1С на -184,864.77 (не выставлено в 1С: 3); Сначала выяснить +1,902,926.24 (начальный разрыв, недостающие акты, спорные суммы) | I14: 186 | J14: 2 | K14: =C14+D14+E14 | L14: =ROUND(K14-F14-G14-(0.000000002),2)
A15: Салам Экспресс | B15: 2800828.5 | C15: 2767104.1 | D15: -26797.3 | E15: 60699.21 | F15: 2801006 | G15: -7.2759576e-12 | H15: Сдвинуть баланс ETM на -26,797.30 (повторная оплата: 1; оплата не зачислена: 1); Исправить 1С на +60,699.21 (не выставлено в 1С: 2); Сначала выяснить +2,801,005.98 (начальный разрыв, недостающие акты, спорные суммы) | I15: 10 | J15: 0 | K15: =C15+D15+E15 | L15: =ROUND(K15-F15-G15-(0.000000000),2)
A16: Манас Тревел | B16: 1737199.2 | C16: 727989.01 | D16: 489305.26 | E16: 521531.47 | F16: 1738825.8 | G16: -0.05 | H16: Сдвинуть баланс ETM на +489,305.26 (бот не перенёс продажу: 4; оплата не зачислена: 3); Исправить 1С на +521,531.47 (не выставлено в 1С: 7); Сначала выяснить +1,738,825.79 (начальный разрыв, недостающие акты, спорные суммы) | I16: 34 | J16: 0 | K16: =C16+D16+E16 | L16: =ROUND(K16-F16-G16-(0.000000000),2)
A17: Джолдошова Салтанат Сатаревна | B17: -703393.53 | C17: -2501581.6 | D17: 1333859.7 | E17: 476089.01 | F17: -691632.85 | G17: -1.4551915e-11 | H17: Сдвинуть баланс ETM на +1,333,859.73 (дубль списания: 1; бот не перенёс продажу: 3; оплата не зачислена: 8); Исправить 1С на +476,089.01 (не выставлено в 1С: 13); Сначала выяснить -691,632.85 (начальный разрыв, недостающие акты, спорные суммы) | I17: 43 | J17: 0 | K17: =C17+D17+E17 | L17: =ROUND(K17-F17-G17-(0.000000000),2)
A18: Ак-Куу Авиа | B18: 453547.35 | C18: -1147683.2 | D18: 1248601.8 | E18: 338266.78 | F18: 439192.17 | G18: -6.77 | H18: Сдвинуть баланс ETM на +1,248,601.82 (дубль списания: 2; бот не перенёс продажу: 5; повторная оплата: 1; оплата не зачислена: 5); Исправить 1С на +338,266.78 (не выставлено в 1С: 14); Сначала выяснить +439,192.17 (начальный разрыв, недостающие акты, спорные суммы) | I18: 76 | J18: 0 | K18: =C18+D18+E18 | L18: =ROUND(K18-F18-G18-(-0.000000001),2)
A19: ИССЫК ТРИП | B19: 0 | C19: -1979507.3 | D19: 1067908.8 | E19: 365663.13 | F19: -545934.4 | G19: -0.95 | H19: Сдвинуть баланс ETM на +1,067,908.82 (дубль списания: 1; бот не перенёс продажу: 5; повторная оплата: 1; оплата не зачислена: 5); Исправить 1С на +365,663.13 (не выставлено в 1С: 4); Сначала выяснить -545,934.40 (начальный разрыв, недостающие акты, спорные суммы) | I19: 104 | J19: 1 | K19: =C19+D19+E19 | L19: =ROUND(K19-F19-G19-(0.000000000),2)
A20: Кадырова Айнура Жумабекевна | B20: 0 | C20: -1954142.9 | D20: 1692737.7 | E20: 261566.36 | F20: 160.68 | G20: 0.5 | H20: Сдвинуть баланс ETM на +1,692,737.73 (бот не перенёс продажу: 3; оплата не зачислена: 6); Исправить 1С на +261,566.36 (не выставлено в 1С: 7); Сначала выяснить +160.68 (начальный разрыв, недостающие акты, спорные суммы) | I20: 24 | J20: 0 | K20: =C20+D20+E20 | L20: =ROUND(K20-F20-G20-(0.000000001),2)
A21: ЧОЛПОН ТУР | B21: -404589.84 | C21: -1727139.1 | D21: 961494.6 | E21: 45627.75 | F21: -720016.73 | G21: 0 | H21: Сдвинуть баланс ETM на +961,494.60 (бот не перенёс продажу: 1; оплата не зачислена: 4); Исправить 1С на +45,627.75; Сначала выяснить -720,016.73 (начальный разрыв, недостающие акты, спорные суммы) | I21: 50 | J21: 2 | K21: =C21+D21+E21 | L21: =ROUND(K21-F21-G21-(0.000000000),2)
A22: Ыйык Тур | B22: 17858.87 | C22: -1667561.3 | D22: 1514597.3 | E22: 171945.45 | F22: 18981.39 | G22: 2.1827873e-11 | H22: Сдвинуть баланс ETM на +1,514,597.28 (дубль списания: 1; бот не перенёс продажу: 2; повторная оплата: 2; оплата не зачислена: 7); Исправить 1С на +171,945.45 (не выставлено в 1С: 3); Сначала выяснить +18,981.39 (начальный разрыв, недостающие акты, спорные суммы) | I22: 39 | J22: 0 | K22: =C22+D22+E22 | L22: =ROUND(K22-F22-G22-(0.000000000),2)
A23: ОсОО Ала-Тоо Эйр | B23: -1194328.2 | C23: -1271085.9 | D23: -205594.19 | E23: 282283.89 | F23: -1194396.2 | G23: -1.4551915e-11 | H23: Сдвинуть баланс ETM на -205,594.19 (бот не перенёс продажу: 1; повторная оплата: 1); Исправить 1С на +282,283.89; Сначала выяснить -1,194,396.23 (начальный разрыв, недостающие акты, спорные суммы) | I23: 8 | J23: 0 | K23: =C23+D23+E23 | L23: =ROUND(K23-F23-G23-(-0.000000000),2)
A24: КУТ ЭЙР | B24: 350463.58 | C24: -973150.62 | D24: 1268900 | E24: 58617.52 | F24: 354366.9 | G24: 2.5465852e-11 | H24: Сдвинуть баланс ETM на +1,268,900.00 (оплата не зачислена: 6); Исправить 1С на +58,617.52 (не выставлено в 1С: 2); Сначала выяснить +354,366.90 (начальный разрыв, недостающие акты, спорные суммы) | I24: 13 | J24: 0 | K24: =C24+D24+E24 | L24: =ROUND(K24-F24-G24-(-0.000000000),2)
A25: ТАЛАС ЛАЙН | B25: 0 | C25: -1552513.3 | D25: 1385355.4 | E25: 122057.66 | F25: -45100.25 | G25: 2.1827873e-11 | H25: Сдвинуть баланс ETM на +1,385,355.42 (дубль списания: 2; оплата не зачислена: 4); Исправить 1С на +122,057.66 (не выставлено в 1С: 3); Сначала выяснить -45,100.25 (начальный разрыв, недостающие акты, спорные суммы) | I25: 19 | J25: 0 | K25: =C25+D25+E25 | L25: =ROUND(K25-F25-G25-(0.000000000),2)
A26: Kumtor Tours | B26: 0 | C26: -1370580.2 | D26: 1370323.8 | E26: -5.8207661e-11 | F26: -256.42 | G26: -1.0913936e-11 | H26: Сдвинуть баланс ETM на +1,370,323.80 (дубль списания: 1; оплата не зачислена: 3); Сначала выяснить -256.42 (начальный разрыв, недостающие акты, спорные суммы) | I26: 9 | J26: 0 | K26: =C26+D26+E26 | L26: =ROUND(K26-F26-G26-(-0.000000000),2)
A27: Абдылда уулу Б. | B27: 0 | C27: -1349195.8 | D27: 1073315.9 | E27: 274924.88 | F27: -955.03 | G27: -4.0017767e-11 | H27: Сдвинуть баланс ETM на +1,073,315.90 (бот не перенёс продажу: 5; повторная оплата: 1; оплата не зачислена: 5); Исправить 1С на +274,924.88 (не выставлено в 1С: 6); Сначала выяснить -955.03 (начальный разрыв, недостающие акты, спорные суммы) | I27: 52 | J27: 0 | K27: =C27+D27+E27 | L27: =ROUND(K27-F27-G27-(-0.000000000),2)
A28: Aylana Tour | B28: -155441.16 | C28: -1295071.4 | D28: 863828.28 | E28: 276225.12 | F28: -155017.99 | G28: -7.2759576e-12 | H28: Сдвинуть баланс ETM на +863,828.28 (бот не перенёс продажу: 1; оплата не зачислена: 3); Исправить 1С на +276,225.12 (не выставлено в 1С: 5); Сначала выяснить -155,017.99 (начальный разрыв, недостающие акты, спорные суммы) | I28: 15 | J28: 0 | K28: =C28+D28+E28 | L28: =ROUND(K28-F28-G28-(-0.000000000),2)
A29: Джолдош уулу Эмир | B29: 0 | C29: -1000296.3 | D29: 1107083.8 | E29: -106557.1 | F29: 230.36 | G29: -1.4551915e-11 | H29: Сдвинуть баланс ETM на +1,107,083.81 (оплата не зачислена: 5); Исправить 1С на -106,557.10; Сначала выяснить +230.36 (начальный разрыв, недостающие акты, спорные суммы) | I29: 12 | J29: 0 | K29: =C29+D29+E29 | L29: =ROUND(K29-F29-G29-(-0.000000001),2)
A30: Байтур Трип | B30: 0 | C30: -1135319.5 | D30: 863445.63 | E30: 182592.31 | F30: -89281.6 | G30: 2.910383e-11 | H30: Сдвинуть баланс ETM на +863,445.63 (бот не перенёс продажу: 1; оплата не зачислена: 2); Исправить 1С на +182,592.31 (не выставлено в 1С: 5); Сначала выяснить -89,281.60 (начальный разрыв, недостающие акты, спорные суммы) | I30: 19 | J30: 0 | K30: =C30+D30+E30 | L30: =ROUND(K30-F30-G30-(0.000000000),2)
A31: Бейшенова Н. Ч. | B31: 0 | C31: -1023080.7 | D31: 1076205.7 | E31: -53538.75 | F31: -413.71 | G31: -2.910383e-11 | H31: Сдвинуть баланс ETM на +1,076,205.71 (бот не перенёс продажу: 1; оплата не зачислена: 4); Исправить 1С на -53,538.75 (не выставлено в 1С: 2); Сначала выяснить -413.71 (начальный разрыв, недостающие акты, спорные суммы) | I31: 11 | J31: 0 | K31: =C31+D31+E31 | L31: =ROUND(K31-F31-G31-(0.000000000),2)
A32: Sunrise Tours | B32: 78399.4 | C32: -965356.77 | D32: 1023642.2 | E32: 20437 | F32: 78722.38 | G32: 7.2759576e-12 | H32: Сдвинуть баланс ETM на +1,023,642.15 (дубль списания: 2; оплата не зачислена: 3); Исправить 1С на +20,437.00; Сначала выяснить +78,722.38 (начальный разрыв, недостающие акты, спорные суммы) | I32: 14 | J32: 0 | K32: =C32+D32+E32 | L32: =ROUND(K32-F32-G32-(0.000000000),2)
A33: Жолчу кызы А. | B33: 0 | C33: -1054427.7 | D33: 823200 | E33: 109666.05 | F33: -121561.69 | G33: 0 | H33: Сдвинуть баланс ETM на +823,200.00 (оплата не зачислена: 3); Исправить 1С на +109,666.05 (не выставлено в 1С: 2); Сначала выяснить -121,561.69 (начальный разрыв, недостающие акты, спорные суммы) | I33: 39 | J33: 1 | K33: =C33+D33+E33 | L33: =ROUND(K33-F33-G33-(0.000000000),2)
A34: ОсОО Алтын Эйр | B34: 0 | C34: -1047879.5 | D34: 977000 | E34: 68541.66 | F34: -2337.83 | G34: 2.910383e-11 | H34: Сдвинуть баланс ETM на +977,000.00 (оплата не зачислена: 3); Исправить 1С на +68,541.66 (не выставлено в 1С: 2); Сначала выяснить -2,337.83 (начальный разрыв, недостающие акты, спорные суммы) | I34: 16 | J34: 0 | K34: =C34+D34+E34 | L34: =ROUND(K34-F34-G34-(0.000000001),2)
A35: Жибек Эйр | B35: 253712.49 | C35: -539022.64 | D35: 730395.41 | E35: 18942.32 | F35: 210315.09 | G35: 1.8189894e-11 | H35: Сдвинуть баланс ETM на +730,395.41 (бот не перенёс продажу: 1; повторная оплата: 1; оплата не зачислена: 4); Исправить 1С на +18,942.32; Сначала выяснить +210,315.09 (начальный разрыв, недостающие акты, спорные суммы) | I35: 137 | J35: 2 | K35: =C35+D35+E35 | L35: =ROUND(K35-F35-G35-(0.000000000),2)
A36: Ак-Куу Тур | B36: 0 | C36: -924681.85 | D36: 377308.2 | E36: 542077.42 | F36: -5296.23 | G36: -4.0017767e-11 | H36: Сдвинуть баланс ETM на +377,308.20 (оплата не зачислена: 1); Исправить 1С на +542,077.42 (не выставлено в 1С: 5); Сначала выяснить -5,296.23 (начальный разрыв, недостающие акты, спорные суммы) | I36: 24 | J36: 0 | K36: =C36+D36+E36 | L36: =ROUND(K36-F36-G36-(0.000000000),2)
A37: Абдыраманова Д. А. | B37: 0 | C37: -921359.2 | D37: 815618.71 | E37: 93239.82 | F37: -12500.67 | G37: 2.910383e-11 | H37: Сдвинуть баланс ETM на +815,618.71 (бот не перенёс продажу: 1; оплата не зачислена: 2); Исправить 1С на +93,239.82 (не выставлено в 1С: 1); Сначала выяснить -12,500.67 (начальный разрыв, недостающие акты, спорные суммы) | I37: 9 | J37: 0 | K37: =C37+D37+E37 | L37: =ROUND(K37-F37-G37-(0.000000000),2)
A38: Манас Тур | B38: 195994.52 | C38: -507459.86 | D38: 606654.7 | E38: 96582.32 | F38: 195777.16 | G38: -7.2759576e-12 | H38: Сдвинуть баланс ETM на +606,654.70 (оплата не зачислена: 3); Исправить 1С на +96,582.32 (не выставлено в 1С: 4); Сначала выяснить +195,777.16 (начальный разрыв, недостающие акты, спорные суммы) | I38: 13 | J38: 0 | K38: =C38+D38+E38 | L38: =ROUND(K38-F38-G38-(0.000000000),2)
A39: Bishkek Fly | B39: -265149.11 | C39: -883308.38 | D39: 591694.7 | E39: 26502 | F39: -265111.68 | G39: 0 | H39: Сдвинуть баланс ETM на +591,694.70 (оплата не зачислена: 2); Исправить 1С на +26,502.00 (не выставлено в 1С: 1); Сначала выяснить -265,111.68 (начальный разрыв, недостающие акты, спорные суммы) | I39: 7 | J39: 0 | K39: =C39+D39+E39 | L39: =ROUND(K39-F39-G39-(0.000000000),2)
A40: Issyk-Kul Air | B40: 1.1641532e-10 | C40: -807992.72 | D40: 698600 | E40: 109449.63 | F40: 60.06 | G40: -3.15 | H40: Сдвинуть баланс ETM на +698,600.00 (оплата не зачислена: 1); Исправить 1С на +109,449.63 (не выставлено в 1С: 3); Сначала выяснить +60.06 (начальный разрыв, недостающие акты, спорные суммы) | I40: 8 | J40: 0 | K40: =C40+D40+E40 | L40: =ROUND(K40-F40-G40-(0.000000000),2)
A41: Эсенбеков Кубат Элдияревич | B41: 0 | C41: -750334.62 | D41: 679765.4 | E41: 68944 | F41: -1625.22 | G41: 2.910383e-11 | H41: Сдвинуть баланс ETM на +679,765.40 (бот не перенёс продажу: 1; оплата не зачислена: 4); Исправить 1С на +68,944.00 (не выставлено в 1С: 3); Сначала выяснить -1,625.22 (начальный разрыв, недостающие акты, спорные суммы) | I41: 15 | J41: 0 | K41: =C41+D41+E41 | L41: =ROUND(K41-F41-G41-(-0.000000000),2)
...

Sheet Мост
A1: Баланс-мост по субагентам (без заплаток): разрыв на конец = начальный разрыв + сумма найденных причин
A2: Каждая строка 1С и ETM попала ровно в одну колонку. «Не объяснено» — формула. Колонки «акт не выгружен» и «скачок через пропуск» — честно нераспределённые суммы, а не ошибки.
A3: Субагент | B3: Разрыв на конец | C3: Разрыв на начало | D3: 1С: разрыв между актами | E3: 1С: скачок через пропущенный акт | F3: 1С: арифметика акта | G3: Округления сошедшихся групп | H3: Сумма: ошибка 1С | I3: Сумма: ошибка бота | J3: Сумма: нужна проверка | K3: Двойное списание | L3: Бот не перенёс продажу | M3: Только 1С, без реестра | N3: Есть в ETM, нет в 1С | O3: Войд не закрыт | P3: ETM: акт не выгружен | Q3: Оплата не проведена в 1С | R3: Оплата не зачислена в ETM | S3: Повторная оплата | T3: Оплата не тому субагенту | U3: Оплата: акт не выгружен | V3: Сумма причин | W3: Не объяснено (формула)
A4: Ak-Bulak Voyage | B4: 561508.28 | C4: 0 | D4: 0 | E4: 501087.88 | F4: 1.4551915e-10 | G4: 0 | H4: 0 | I4: 0 | J4: -97936.08 | K4: 0 | L4: 0 | M4: 0 | N4: 0 | O4: 0 | P4: -404443.52 | Q4: 0 | R4: 0 | S4: 562800 | T4: 0 | U4: 0 | V4: =SUM(C4:U4) | W4: =ROUND(B4-V4,4)
A5: Ala-Too Travel | B5: -3317307.5 | C5: -3233430.5 | D5: 0 | E5: 0 | F5: -1.2369128e-10 | G5: -1.4551915e-11 | H5: 0 | I5: 0 | J5: -17.83 | K5: 0 | L5: 0 | M5: 0 | N5: -83859.22 | O5: 0 | P5: 0 | Q5: 0 | R5: 0 | S5: 0 | T5: 0 | U5: 0 | V5: =SUM(C5:U5) | W5: =ROUND(B5-V5,4)
A6: Aylana Tour | B6: -1295071.4 | C6: -155441.16 | D6: 27500 | E6: 0 | F6: -1.1641532e-10 | G6: -7.2759576e-12 | H6: -69823.61 | I6: -1903.84 | J6: 423.17 | K6: 0 | L6: 43175.56 | M6: 0 | N6: -233901.51 | O6: 0 | P6: 0 | Q6: 0 | R6: -905100 | S6: 0 | T6: 0 | U6: 0 | V6: =SUM(C6:U6) | W6: =ROUND(B6-V6,4)
A7: Bishkek Fly | B7: -883308.38 | C7: -265149.11 | D7: 0 | E7: 0 | F7: 0 | G7: 0 | H7: -13526 | I7: -1094.7 | J7: 37.43 | K7: 0 | L7: 0 | M7: 0 | N7: -12976 | O7: 0 | P7: 0 | Q7: 0 | R7: -590600 | S7: 0 | T7: 0 | U7: 0 | V7: =SUM(C7:U7) | W7: =ROUND(B7-V7,4)
A8: Blue Bird Travel | B8: -234553.82 | C8: -1.0913936e-11 | D8: 0 | E8: 0 | F8: -8.0035534e-11 | G8: -1.4551915e-11 | H8: 7200 | I8: -16352.1 | J8: -4235.84 | K8: 0 | L8: 0 | M8: 0 | N8: -197465.88 | O8: 0 | P8: 0 | Q8: 0 | R8: -149400 | S8: 125700 | T8: 0 | U8: 0 | V8: =SUM(C8:U8) | W8: =ROUND(B8-V8,4)
A9: Issyk-Kul Air | B9: -807992.72 | C9: 1.1641532e-10 | D9: 0 | E9: 0 | F9: 1.1641532e-10 | G9: -3.15 | H9: 8171.37 | I9: 0 | J9: 60.06 | K9: 0 | L9: 0 | M9: 0 | N9: -117621 | O9: 0 | P9: 0 | Q9: 0 | R9: -698600 | S9: 0 | T9: 0 | U9: 0 | V9: =SUM(C9:U9) | W9: =ROUND(B9-V9,4)
A10: Jailoo Trip | B10: 58975.46 | C10: 5.8207661e-11 | D10: 0 | E10: 0 | F10: -1.4551915e-10 | G10: 1.4551915e-11 | H10: -800 | I10: 7189.48 | J10: 101.32 | K10: 0 | L10: 73085.04 | M10: 0 | N10: -20600.38 | O10: 0 | P10: 0 | Q10: 0 | R10: 0 | S10: 0 | T10: 0 | U10: 0 | V10: =SUM(C10:U10) | W10: =ROUND(B10-V10,4)
A11: Karakol Express | B11: -3899769.5 | C11: 23846.3 | D11: 0 | E11: 0 | F11: -3.4924597e-10 | G11: -4.65 | H11: 342534.01 | I11: -8013.7 | J11: 26014.83 | K11: -65928.6 | L11: 270524.17 | M11: 0 | N11: -718741.85 | O11: 0 | P11: 0 | Q11: 0 | R11: -4274600 | S11: 504600 | T11: 0 | U11: 0 | V11: =SUM(C11:U11) | W11: =ROUND(B11-V11,4)
A12: Kumtor Tours | B12: -1370580.2 | C12: 0 | D12: 0 | E12: 0 | F12: 5.8207661e-11 | G12: -1.0913936e-11 | H12: 0 | I12: -27000 | J12: -256.42 | K12: -28223.8 | L12: 0 | M12: 0 | N12: 0 | O12: 0 | P12: 0 | Q12: 0 | R12: -1315100 | S12: 0 | T12: 0 | U12: 0 | V12: =SUM(C12:U12) | W12: =ROUND(B12-V12,4)
A13: Nomad Trip | B13: 24188.38 | C13: 0 | D13: 107557.1 | E13: 0 | F13: -6.5483619e-11 | G13: 1.4551915e-11 | H13: 0 | I13: 424.64 | J13: -123.95 | K13: 0 | L13: 0 | M13: 0 | N13: -83669.41 | O13: 0 | P13: 0 | Q13: 0 | R13: 0 | S13: 0 | T13: 0 | U13: 0 | V13: =SUM(C13:U13) | W13: =ROUND(B13-V13,4)
A14: Silk Route Air | B14: 97886.44 | C14: 170347.21 | D14: 0 | E14: 0 | F14: 0 | G14: -7.2759576e-12 | H14: 1345.55 | I14: 2648.45 | J14: 450.34 | K14: -19682 | L14: 0 | M14: 0 | N14: -57223.11 | O14: 0 | P14: 0 | Q14: 0 | R14: 0 | S14: 0 | T14: 0 | U14: 0 | V14: =SUM(C14:U14) | W14: =ROUND(B14-V14,4)
A15: SkyWay Travel | B15: -8740000 | C15: 0 | D15: 27500 | E15: 0 | F15: 1.9390427e-09 | G15: -4.91 | H15: -224084.64 | I15: -2384.48 | J15: -27327.17 | K15: -128165.95 | L15: 354548.84 | M15: 0 | N15: -1109681.7 | O15: 0 | P15: 0 | Q15: 0 | R15: -8041200 | S15: 410800 | T15: 0 | U15: 0 | V15: =SUM(C15:U15) | W15: =ROUND(B15-V15,4)
... A103: Эсенбекова Айгуль Нурбекевна | B103: -448734.06 | C103: 0 | D103: 0 | E103: 0 | F103: -2.0008883e-11 | G103: 0 | H103: 0 | I103: 407.8 | J103: 0 | K103: 0 | L103: 0 | M103: 0 | N103: -40641.86 | O103: 0 | P103: 0 | Q103: 0 | R103: -408500 | S103: 0 | T103: 0 | U103: 0 | V103: =SUM(C103:U103) | W103: =ROUND(B103-V103,4)
A104: ИТОГО | B104: =SUM(B4:B103) | C104: =SUM(C4:C103) | D104: =SUM(D4:D103) | E104: =SUM(E4:E103) | F104: =SUM(F4:F103) | G104: =SUM(G4:G103) | H104: =SUM(H4:H103) | I104: =SUM(I4:I103) | ... W104: =SUM(W4:W103)

Sheet Мост по месяцам
A1: Помесячная проверка тождества (без подгонки)
A2: Изменение разрыва за месяц обязано равняться: арифметика акта + оборот 1С + оборот ETM. «Остаток тождества» — формула.
A3: Субагент | B3: Месяц | C3: Сальдо 1С начало | D3: Сальдо 1С конец | E3: Оборот 1С | F3: Баланс ETM начало | G3: Баланс ETM конец | H3: Оборот ETM | I3: Разрыв начало | J3: Разрыв конец | K3: Арифметика акта | L3: Разрыв сальдо между актами? | M3: Скачок сальдо 1С на входе | N3: Остаток тождества (≈0)
A4: Ak-Bulak Voyage | B4: 2026-01 | C4: 0 | D4: -398788.25 | E4: -398788.25 | F4: 0 | G4: 398781.33 | H4: 398781.33 | I4: 0 | J4: -6.92 | K4: 0 | L4: FALSE | M4: 0 | N4: =ROUND((J4-I4)-(K4+E4+H4),4)
A5: Ak-Bulak Voyage | B5: 2026-03 | C5: 102299.63 | D5: -162591.5 | E5: -264891.13 | F5: -103591.35 | G5: 724099.78 | H5: 827691.13 | I5: -1291.72 | J5: 561508.28 | K5: 0 | L5: FALSE | M5: 501087.88 | N5: =ROUND((J5-I5)-(K5+E5+H5),4)
A6: Ak-Bulak Voyage | B6: 2026-04 | C6: -162591.5 | D6: -253907.41 | E6: -91315.91 | F6: 724099.78 | G6: 815415.69 | H6: 91315.91 | I6: 561508.28 | J6: 561508.28 | K6: -2.910383e-11 | L6: FALSE | M6: 0 | N6: =ROUND((J6-I6)-(K6+E6+H6),4)
A7: Ak-Bulak Voyage | B7: 2026-05 | C7: -253907.41 | D7: -610056.98 | E7: -356149.57 | F7: 815415.69 | G7: 1171565.3 | H7: 356149.57 | I7: 561508.28 | J7: 561508.28 | K7: 1.1641532e-10 | L7: FALSE | M7: 0 | N7: =ROUND((J7-I7)-(K7+E7+H7),4)
A8: Ak-Bulak Voyage | B8: 2026-06 | C8: -610056.98 | D8: -326732.13 | E8: 283324.85 | F8: 1171565.3 | G8: 888240.41 | H8: -283324.85 | I8: 561508.28 | J8: 561508.28 | K8: 0 | L8: FALSE | M8: 0 | N8: =ROUND((J8-I8)-(K8+E8+H8),4)
A9: Ak-Bulak Voyage | B9: 2026-07 | C9: -326732.13 | D9: -377925.16 | E9: -51193.03 | F9: 888240.41 | G9: 939433.44 | H9: 51193.03 | I9: 561508.28 | J9: 561508.28 | K9: 5.8207661e-11 | L9: FALSE | M9: 0 | N9: =ROUND((J9-I9)-(K9+E9+H9),4)
A10: Ala-Too Travel | B10: 2026-01 | C10: 0 | D10: -147353.8 | E10: -147353.8 | F10: -3233430.5 | G10: -3086076.7 | H10: 147353.8 | I10: -3233430.5 | J10: -3233430.5 | K10: 0 | L10: FALSE | M10: 0 | N10: =ROUND((J10-I10)-(K10+E10+H10),4)
A11: Ala-Too Travel | B11: 2026-02 | C11: -147353.8 | D11: -266377.05 | E11: -119023.25 | F11: -3086076.7 | G11: -2967053.4 | H11: 119023.25 | I11: -3233430.5 | J11: -3233430.5 | K11: 0 | L11: FALSE | M11: 0 | N11: =ROUND((J11-I11)-(K11+E11+H11),4)
A12: Ala-Too Travel | B12: 2026-03 | C12: -266377.05 | D12: -1072376.2 | E12: -805999.16 | F12: -2967053.4 | G12: -2161054.3 | H12: 805999.16 | I12: -3233430.5 | J12: -3233430.5 | K12: 0 | L12: FALSE | M12: 0 | N12: =ROUND((J12-I12)-(K12+E12+H12),4)
A13: Ala-Too Travel | B13: 2026-04 | C13: -1072376.2 | D13: -1004260.1 | E13: 68116.08 | F13: -2161054.3 | G13: -2229170.4 | H13: -68116.08 | I13: -3233430.5 | J13: -3233430.5 | K13: -1.1641532e-10 | L13: FALSE | M13: 0 | N13: =ROUND((J13-I13)-(K13+E13+H13),4)
A14: Ala-Too Travel | B14: 2026-05 | C14: -1004260.1 | D14: -563010.87 | E14: 441249.26 | F14: -2229170.4 | G14: -2670419.6 | H14: -441249.26 | I14: -3233430.5 | J14: -3233430.5 | K14: 0 | L14: FALSE | M14: 0 | N14: =ROUND((J14-I14)-(K14+E14+H14),4)
A15: Ala-Too Travel | B15: 2026-06 | C15: -563010.87 | D15: -434234.69 | E15: 128776.18 | F15: -2670419.6 | G15: -2831462.3 | H15: -161042.72 | I15: -3233430.5 | J15: -3265697 | K15: 0 | L15: FALSE | M15: 0 | N15: =ROUND((J15-I15)-(K15+E15+H15),4)
... A679: Эсенбекова Айгуль Нурбекевна | B679: 2026-07 | C679: -10487.26 | D679: -312903.7 | E679: -302416.44 | F679: -435101.4 | G679: -135830.36 | H679: 299271.04 | I679: -445588.66 | J679: -448734.06 | K679: 0 | L679: FALSE | M679: 0 | N679: =ROUND((J679-I679)-(K679+E679+H679),4)

Sheet Расхождения
A1: Расхождения по группам билетов (1,792 строк — найденные случаи с источником и уверенностью, а не «ошибки»)
A2: Уверенность: A — подтверждено вторым источником; B — правдоподобная гипотеза; C — данных недостаточно.
A3: ID | B3: Субагент | C3: Билеты | D3: Тип | E3: Источник ошибки | F3: Уверенность | G3: Сумма 1С | H3: Сумма ETM | I3: Сумма реестра | J3: Остаток 1С+ETM | K3: Дата ETM | L3: Дата 1С | M3: Паттерн суммы | N3: Кто проверяет | O3: Сотрудник реестра | P3: Что произошло | Q3: ETM txn
A4: G05983 | B4: БАЙТУР ТУРИЗМ | C4: 2559102147|2559102148|2559102151|2559102154 | D4: Есть в ETM, нет в 1С | E4: 1С | F4: A | G4: 0 | H4: -197836 | I4: 2000 | J4: -197836 | K4: 46129.444 | N4: Бухгалтер 1С | O4: k.dzhumaev|n.abdyldaeva | P4: Списание есть в ETM и продажа в реестре, но в 1С нет реализации по этим билетам — счёт не выставлен | Q4: 57212874,57212913,57212845,57212859
A5: G01740 | B5: Karakol Express | C5: 2476319698|2476319699|2476319700|2476319702 | D5: Сумма не сходится | E5: 1С | F5: A | G5: 137827.2 | H5: -317827.2 | I5: 317827.2 | J5: -180000 | K5: 46198.337 | L5: 46198 | M5: TRANSPOSITION | N5: Бухгалтер 1С | O5: d.mambetova | P5: Реестр (317,827.20) совпадает с ETM (317,827.20), а в 1С 137,827.20: неверная сумма в 1С | Q5: 57401206,57401176,57401199,57401164
A6: G09168 | B6: ИССЫК ТРИП | C6: 2461885824|2461885826|2461885828 | D6: Сумма не сходится | E6: 1С | F6: A | G6: 130386 | H6: -310386 | I6: 310386 | J6: -180000 | K6: 46220.803 | L6: 46220 | M6: TRANSPOSITION | N6: Бухгалтер 1С | O6: d.mambetova | P6: Реестр (310,386.00) совпадает с ETM (310,386.00), а в 1С 130,386.00: неверная сумма в 1С | Q6: 57467395
A7: G05669 | B7: Ак-Куу Тур | C7: 2559099449|2559099450 | D7: Сумма не сходится | E7: 1С | F7: A | G7: 133571.72 | H7: -313571.72 | I7: 313571.82 | J7: -180000 | K7: 46219.342 | L7: 46219 | M7: TRANSPOSITION | N7: Бухгалтер 1С | O7: k.dzhumaev | P7: Реестр (313,571.82) совпадает с ETM (313,571.72), а в 1С 133,571.72: неверная сумма в 1С | Q7: 57463685,57463705
A8: G00258 | B8: Aylana Tour | C8: 2559101779|2559101780|2559101783 | D8: Есть в ETM, нет в 1С | E8: 1С | F8: A | G8: 0 | H8: -163943.25 | J8: -163943.25 | K8: 46217.372 | N8: Бухгалтер 1С | P8: Списание есть в ETM, но в 1С нет реализации по этим билетам — счёт не выставлен | Q8: 57458399
A9: G13883 | B9: ТЯНЬ-ШАНЬ ЭКСПРЕСС | C9: 2416943100|2416943101|2416943104 | D9: Есть в ETM, нет в 1С | E9: 1С | F9: A | G9: 0 | H9: -144706.56 | I9: 144706.56 | J9: -144706.56 | K9: 46194.418 | N9: Бухгалтер 1С | O9: g.omurbekova | P9: Списание есть в ETM и продажа в реестре, но в 1С нет реализации по этим билетам — счёт не выставлен | Q9: 57386616,57386643,57386599
A10: G05473 | B10: Ак-Куу Тур | C10: 2416944535|2416944536|2416944539 | D10: Есть в ETM, нет в 1С | E10: 1С | F10: A | G10: 0 | H10: -138159.9 | I10: 138159.9 | J10: -138159.9 | K10: 46108.459 | N10: Бухгалтер 1С | O10: b.isakov | P10: Списание есть в ETM и продажа в реестре, но в 1С нет реализации по этим билетам — счёт не выставлен | Q10: 57175913,57175908,57175910
A11: G13979 | B11: ТЯНЬ-ШАНЬ ЭКСПРЕСС | C11: 2559103101|2559103102|2559103105 | D11: Есть в ETM, нет в 1С | E11: 1С | F11: A | G11: 0 | H11: -132888.24 | I11: 132888.26 | J11: -132888.24 | K11: 46127.463 | N11: Бухгалтер 1С | O11: d.mambetova | P11: Списание есть в ETM и продажа в реестре, но в 1С нет реализации по этим билетам — счёт не выставлен | Q11: 57209313,57209349,57209331
A12: G03114 | B12: SkyWay Travel | C12: 2461884640|2461884642|2461884643 | D12: Есть в ETM, нет в 1С | E12: 1С | F12: A | G12: 0 | H12: -130356 | I12: 130356 | J12: -130356 | K12: 46089.339 | N12: Бухгалтер 1С | O12: n.abdyldaeva | P12: Списание есть в ETM и продажа в реестре, но в 1С нет реализации по этим билетам — счёт не выставлен | Q12: 57132455,57132492,57132468
A13: G13070 | B13: Сатар уулу Санжар | C13: 2460733285|2460733286|2460733289 | D13: Есть в реестре и 1С, нет в ETM | E13: Бот ETM | F13: A | G13: 129948 | H13: 0 | I13: 129948 | J13: 129948 | L13: 46096 | N13: Разработчик/поддержка бота ETM | O13: b.isakov | P13: Продажа есть в реестре и в 1С, но бот не перенёс её на баланс ETM — списания нет
A14: G01404 | B14: Karakol Express | C14: 2460732939|2460732941|2460732944|2460732945 | D14: Есть в ETM, нет в 1С | E14: 1С | F14: A | G14: 0 | H14: -127788 | I14: 127788 | J14: -127788 | K14: 46185.558 | N14: Бухгалтер 1С | O14: n.abdyldaeva | P14: Списание есть в ETM и продажа в реестре, но в 1С нет реализации по этим билетам — счёт не выставлен | Q14: 57360780,57360839,57360827,57360818
A15: G12266 | B15: САЛАМ ЭЙР | C15: 2416941997|2416942000 | D15: Есть в ETM, нет в 1С | E15: 1С | F15: A | G15: 0 | H15: -127600.2 | I15: 127600.2 | J15: -127600.2 | K15: 46208.551 | N15: Бухгалтер 1С | O15: d.mambetova | P15: Списание есть в ETM и продажа в реестре, но в 1С нет реализации по этим билетам — счёт не выставлен | Q15: 57430999,57430973
A16: G04364 | B16: Абдылда уулу Б. | C16: 2461883509|2461883511|2461883513|2461883514 | D16: Есть в ETM, нет в 1С | E16: 1С | F16: A | G16: 0 | H16: -126240 | I16: 126240 | J16: -126240 | K16: 46166.606 | N16: Бухгалтер 1С | O16: a.toktosunova | P16: Списание есть в ETM и продажа в реестре, но в 1С нет реализации по этим билетам — счёт не выставлен | Q16: 57313272
A17: G10485 | B17: Манас Тревел | C17: 2559102575|2559102576|2559102578 | D17: Есть в реестре и 1С, нет в ETM | E17: Бот ETM | F17: A | G17: 125193.84 | H17: 0 | I17: 125193.84 | J17: 125193.84 | L17: 46148 | N17: Разработчик/поддержка бота ETM | O17: a.toktosunova | P17: Продажа есть в реестре и в 1С, но бот не перенёс её на баланс ETM — списания нет
A18: G14220 | B18: Урматова Айпери Нурбековна | C18: 2552671225|2552671226 | D18: Есть в реестре и 1С, нет в ETM | E18: Бот ETM | F18: A | G18: 117615.24 | H18: 0 | I18: 117615.25 | J18: 117615.24 | L18: 46085 | N18: Разработчик/поддержка бота ETM | O18: d.mambetova | P18: Продажа есть в реестре и в 1С, но бот не перенёс её на баланс ETM — списания нет
A19: G09824 | B19: Кенешова Чолпон Таалайовна | C19: 2416941910|2416941911 | D19: Есть в реестре и 1С, нет в ETM | E19: Бот ETM | F19: A | G19: 116129.76 | H19: 0 | I19: 116129.75 | J19: 116129.76 | L19: 46052 | N19: Разработчик/поддержка бота ETM | O19: d.mambetova | P19: Продажа есть в реестре и в 1С, но бот не перенёс её на баланс ETM — списания нет
A20: G05815 | B20: Асанов Кубат Чынаревич | C20: 2416943380|2416943382 | D20: Есть в ETM, нет в 1С | E20: 1С | F20: A | G20: 0 | H20: -115067.94 | J20: -115067.94 | K20: 46179.663 | N20: Бухгалтер 1С | P20: Списание есть в ETM, но в 1С нет реализации по этим билетам — счёт не выставлен | Q20: 57346685
A21: G07555 | B21: Жолчу кызы А. | C21: 2552667333|2552667336 | D21: Есть в ETM, нет в 1С | E21: 1С | F21: A | G21: 0 | H21: -110088.8 | I21: 2023.2 | J21: -110088.8 | K21: 46215.563 | N21: Бухгалтер 1С | O21: a.toktosunova|k.dzhumaev | P21: Списание есть в ETM и продажа в реестре, но в 1С нет реализации по этим билетам — счёт не выставлен | Q21: 57452130
A22: G10423 | B22: Манас Тревел | C22: 2552669638|2552669640|2552669642 | D22: Есть в ETM, нет в 1С | E22: 1С | F22: A | G22: 0 | H22: -106792.92 | I22: 106792.92 | J22: -106792.92 | K22: 46089.393 | N22: Бухгалтер 1С | O22: e.satarov | P22: Списание есть в ETM и продажа в реестре, но в 1С нет реализации по этим билетам — счёт не выставлен | Q22: 57132122
A23: G04442 | B23: Абдылда уулу Б. | C23: 2476319155|2476319157|2476319158|2476319159 | D23: Есть в реестре и 1С, нет в ETM | E23: Бот ETM | F23: A | G23: 105761.04 | H23: 0 | I23: 105761.04 | J23: 105761.04 | L23: 46099 | N23: Разработчик/поддержка бота ETM | O23: k.dzhumaev | P23: Продажа есть в реестре и в 1С, но бот не перенёс её на баланс ETM — списания нет
A24: G04751 | B24: Ак-Куу Авиа | C24: 2416942350|2416942353|2416942356|2416942357 | D24: Есть в реестре и 1С, нет в ETM | E24: Бот ETM | F24: A | G24: 104833.2 | H24: 0 | I24: 104833.2 | J24: 104833.2 | L24: 46035 | N24: Разработчик/поддержка бота ETM | O24: a.toktosunova | P24: Продажа есть в реестре и в 1С, но бот не перенёс её на баланс ETM — списания нет
A25: G04540 | B25: Абдылда уулу Б. | C25: 2559103835|2559103836 | D25: Есть в реестре и 1С, нет в ETM | E25: Бот ETM | F25: A | G25: 98842.08 | H25: 0 | I25: 98842.08 | J25: 98842.08 | L25: 46097 | N25: Разработчик/поддержка бота ETM | O25: a.toktosunova | P25: Продажа есть в реестре и в 1С, но бот не перенёс её на баланс ETM — списания нет
A26: G09676 | B26: Кадырова Айнура Жумабекевна | C26: 2460736923|2460736926|2460736927 | D26: Есть в ETM, нет в 1С | E26: 1С | F26: A | G26: 0 | H26: -97458 | I26: 97458 | J26: -97458 | K26: 46148.78 | N26: Бухгалтер 1С | O26: k.dzhumaev | P26: Списание есть в ETM и продажа в реестре, но в 1С нет реализации по этим билетам — счёт не выставлен | Q26: 57259064,57259120,57259100
A27: G13427 | B27: Сатарова А. О. | C27: 2476314998|2476315000|2476315003 | D27: Есть в реестре и 1С, нет в ETM | E27: Бот ETM | F27: A | G27: 96800.94 | H27: 0 | I27: 96800.94 | J27: 96800.94 | L27: 46102 | N27: Разработчик/поддержка бота ETM | O27: b.isakov | P27: Продажа есть в реестре и в 1С, но бот не перенёс её на баланс ETM — списания нет
A28: G10159 | B28: Манас Вояж | C28: 2552671660|2552671662|2552671665 | D28: Есть в ETM, нет в 1С | E28: 1С | F28: A | G28: 0 | H28: -96385.29 | I28: 96385.298 | J28: -96385.29 | K28: 46114.477 | N28: Бухгалтер 1С | O28: d.mambetova | P28: Списание есть в ETM и продажа в реестре, но в 1С нет реализации по этим билетам — счёт не выставлен | Q28: 57186857,57186863,57186859
A29: G02612 | B29: SkyWay Travel | C29: 2459527020|2459527022|2459527024 | D29: Есть в реестре и 1С, нет в ETM | E29: Бот ETM | F29: A | G29: 95907 | H29: 0 | I29: 95907 | J29: 95907 | L29: 46049 | N29: Разработчик/поддержка бота ETM | O29: g.omurbekova | P29: Продажа есть в реестре и в 1С, но бот не перенёс её на баланс ETM — списания нет
A30: G04713 | B30: Абдыраманова Д. А. | C30: 2552670154|2552670155|2552670158 | D30: Есть в ETM, нет в 1С | E30: 1С | F30: A | G30: 0 | H30: -95039.82 | I30: 95039.82 | J30: -95039.82 | K30: 46230.344 | N30: Бухгалтер 1С | O30: b.isakov | P30: Списание есть в ETM и продажа в реестре, но в 1С нет реализации по этим билетам — счёт не выставлен | Q30: 57492130,57492158,57492136
A31: G09913 | B31: МУРАС ТРИП | C31: 2416943912|2416943914 | D31: Сумма не сходится | E31: 1С | F31: A | G31: -80610.18 | H31: -14225.32 | I31: 14225.32 | J31: -94835.5 | K31: 46214.511 | L31: 46225 | N31: Бухгалтер 1С | O31: b.isakov|e.satarov | P31: Реестр (14,225.32) совпадает с ETM (14,225.32), а в 1С -80,610.18: неверная сумма в 1С | Q31: 57450691,57450661,57477805
A32: G02341 | B32: SkyWay Travel | C32: 2416944456|2416944459 | D32: Сумма не сходится | E32: 1С | F32: A | G32: -70885.77 | H32: -23628.59 | I32: 23628.58 | J32: -94514.36 | K32: 46079.624 | L32: 46136 | N32: Бухгалтер 1С | O32: n.abdyldaeva|r.sydykov | P32: Реестр (23,628.58) совпадает с ETM (23,628.59), а в 1С -70,885.77: неверная сумма в 1С | Q32: 57110804,57110829,57225878
A33: G14715 | B33: ЫЙЫК ЭКСПРЕСС | C33: 2416942558|2416942561 | D33: Есть в реестре и 1С, нет в ETM | E33: Бот ETM | F33: A | G33: 94019.5 | H33: 0 | I33: 94019.5 | J33: 94019.5 | L33: 46148 | N33: Разработчик/поддержка бота ETM | O33: k.dzhumaev | P33: Продажа есть в реестре и в 1С, но бот не перенёс её на баланс ETM — списания нет
A34: G09258 | B34: ИССЫК ТРИП | C34: 2552667309|2552667312 | D34: Есть в реестре и 1С, нет в ETM | E34: Бот ETM | F34: A | G34: 93237.8 | H34: 0 | I34: 93237.8 | J34: 93237.8 | L34: 46159 | N34: Разработчик/поддержка бота ETM | O34: b.isakov | P34: Продажа есть в реестре и в 1С, но бот не перенёс её на баланс ETM — списания нет
A35: G13576 | B35: Сыдыков С. У. | C35: 2552670969|2552670970|2552670973 | D35: Есть в реестре и 1С, нет в ETM | E35: Бот ETM | F35: A | G35: 91517.13 | H35: 0 | I35: 91517.137 | J35: 91517.13 | L35: 46028 | N35: Разработчик/поддержка бота ETM | O35: k.dzhumaev | P35: Продажа есть в реестре и в 1С, но бот не перенёс её на баланс ETM — списания нет
A36: G08989 | B36: ИССЫК ТРИП | C36: 2459526893|2459526894 | D36: Есть в ETM, нет в 1С | E36: 1С | F36: A | G36: 0 | H36: -89440 | I36: 89440 | J36: -89440 | K36: 46151.406 | N36: Бухгалтер 1С | O36: n.abdyldaeva | P36: Списание есть в ETM и продажа в реестре, но в 1С нет реализации по этим билетам — счёт не выставлен | Q36: 57266763,57266742
A37: G06813 | B37: Джолдошова Салтанат Сатаревна | C37: 2559099104|2559099107 | D37: Есть в ETM, нет в 1С | E37: 1С | F37: A | G37: 0 | H37: -89279.04 | I37: 1000 | J37: -89279.04 | K37: 46070.639 | N37: Бухгалтер 1С | O37: b.isakov|d.mambetova | P37: Списание есть в ETM и продажа в реестре, но в 1С нет реализации по этим билетам — счёт не выставлен | Q37: 57094267,57094265
A38: G12224 | B38: САЛАМ ВОЯЖ | C38: 2459528839|2459528840 | D38: Сумма не сходится | E38: Бот ETM | F38: A | G38: 48998.4 | H38: 40089.6 | I38: 48998.4 | J38: 89088 | K38: 46177.491 | L38: 46133 | N38: Разработчик/поддержка бота ETM | O38: b.isakov|g.omurbekova | P38: Реестр (48,998.40) совпадает с 1С (48,998.40), а в ETM -40,089.60: бот перенёс неверную сумму | Q38: 57339940
A39: G07877 | B39: ИП Асанов К. Б. | C39: 2552668100|2552668103|2552668104 | D39: Есть в ETM, нет в 1С | E39: 1С | F39: A | G39: 0 | H39: -87873.87 | I39: 87873.878 | J39: -87873.87 | K39: 46179.546 | N39: Бухгалтер 1С | O39: b.isakov | P39: Списание есть в ETM и продажа в реестре, но в 1С нет реализации по этим билетам — счёт не выставлен | Q39: 57345966,57345926,57345964
A40: G10319 | B40: Манас Тревел | C40: 2460736416|2460736417 | D40: Есть в ETM, нет в 1С | E40: 1С | F40: A | G40: 0 | H40: -87744 | I40: 87744 | J40: -87744 | K40: 46039.666 | N40: Бухгалтер 1С | O40: d.mambetova | P40: Списание есть в ETM и продажа в реестре, но в 1С нет реализации по этим билетам — счёт не выставлен | Q40: 57034828,57034817
...

Sheet Платежи
A1: Платежи: оплаты ETM без поступления в 1С и поступления 1С без оплаты в ETM
A3: Субагент | B3: Дата | C3: Где найдено | D3: Документ/ID | E3: Сумма | F3: Тип | G3: Источник | H3: Уверенность | I3: Что произошло | J3: Влияние на разрыв
A4: Джолдош уулу Руслан | B4: 46136 | C4: 1C | D4: Поступление на р/с, п/п ЦБ-С000203 | E4: 706600 | F4: PAYMENT_NOT_IN_ETM | G4: Бот ETM | H4: B | I4: Поступление 706,600.00 есть в 1С, зачисления на баланс ETM нет | J4: -706600
A5: Issyk-Kul Air | B5: 46207 | C5: 1C | D5: Поступление на р/с, п/п ЦБ-С000536 | E5: 698600 | F5: PAYMENT_NOT_IN_ETM | G5: Бот ETM | H5: B | I5: Поступление 698,600.00 есть в 1С, зачисления на баланс ETM нет | J5: -698600
A6: Ak-Bulak Voyage | B6: 46109.455 | C6: ETM | D6: 57174246 | E6: 562800 | F6: REPEATED_CREDIT | G6: Бот ETM | H6: A | I6: Оплата на 562,800.00 повторно зачислена в ETM через 21.4 ч, в 1С поступление одно | J6: 562800
A7: Ыйык Тур | B7: 46035.539 | C7: ETM | D7: 57021400 | E7: 529600 | F7: REPEATED_CREDIT | G7: Бот ETM | H7: A | I7: Оплата на 529,600.00 повторно зачислена в ETM через 23.7 ч, в 1С поступление одно | J7: 529600
A8: ИССЫК ТРИП | B8: 46065.559 | C8: ETM | D8: 57086445 | E8: 525900 | F8: ETM_PAYMENT_IN_MISSING_ACT_MONTH | G8: Выгрузка 1С | H8: B | I8: Оплата есть в ETM, акт 1С за месяц не выгружен | J8: 525900
A9: Ыйык Тур | B9: 46080 | C9: 1C | D9: Поступление на р/с, п/п ЦБ-С000298 | E9: 506000 | F9: PAYMENT_NOT_IN_ETM | G9: Бот ETM | H9: B | I9: Поступление 506,000.00 есть в 1С, зачисления на баланс ETM нет | J9: -506000
A10: Sunrise Tours | B10: 46092 | C10: 1C | D10: Поступление на р/с, п/п ЦБ-С001532 | E10: 501500 | F10: PAYMENT_NOT_IN_ETM | G10: Бот ETM | H10: B | I10: Поступление 501,500.00 есть в 1С, зачисления на баланс ETM нет | J10: -501500
A11: SkyWay Travel | B11: 46178 | C11: 1C | D11: Поступление на р/с, п/п ЦБ-С001264 | E11: 495300 | F11: PAYMENT_NOT_IN_ETM | G11: Бот ETM | H11: B | I11: Поступление 495,300.00 есть в 1С, зачисления на баланс ETM нет | J11: -495300
A12: Абдыраманова Д. А. | B12: 46173 | C12: 1C | D12: Поступление на р/с, п/п ЦБ-С001306 | E12: 493600 | F12: PAYMENT_NOT_IN_ETM | G12: Бот ETM | H12: B | I12: Поступление 493,600.00 есть в 1С, зачисления на баланс ETM нет | J12: -493600
A13: Осмонова А. Н. | B13: 46160 | C13: 1C | D13: Поступление на р/с, п/п ЦБ-С002359 | E13: 493300 | F13: PAYMENT_NOT_IN_ETM | G13: Бот ETM | H13: B | I13: Поступление 493,300.00 есть в 1С, зачисления на баланс ETM нет | J13: -493300
A14: SkyWay Travel | B14: 46165 | C14: 1C | D14: Поступление на р/с, п/п ЦБ-С001221 | E14: 487700 | F14: PAYMENT_NOT_IN_ETM | G14: Бот ETM | H14: B | I14: Поступление 487,700.00 есть в 1С, зачисления на баланс ETM нет | J14: -487700
A15: Ак-Куу Авиа | B15: 46104 | C15: 1C | D15: Поступление на р/с, п/п ЦБ-С002034 | E15: 486900 | F15: PAYMENT_NOT_IN_ETM | G15: Бот ETM | H15: B | I15: Поступление 486,900.00 есть в 1С, зачисления на баланс ETM нет | J15: -486900
... A331: Чынарова Бурул Джолдошовна | B331: 46148 | C331: 1C | D331: Поступление на р/с, п/п ЦБ-С000048 | E331: 95000 | F331: PAYMENT_NOT_IN_ETM | G331: Бот ETM | H331: B | I331: Поступление 95,000.00 есть в 1С, зачисления на баланс ETM нет | J331: -95000

Sheet Аномалии
A1: Повторные операции и аномалии (67 шт.)
A3: Тип | B3: Субагент | C3: Билеты/документ | D3: Дата | E3: Сумма, KGS | F3: Описание
A4: Повторная оплата | B4: Ak-Bulak Voyage | C4: 57174246 | D4: 46109.455 | E4: 562800 | F4: Оплата на 562,800.00 повторно зачислена в ETM через 21.4 ч, в 1С поступление одно
A5: Повторная оплата | B5: Ыйык Тур | C5: 57021400 | D5: 46035.539 | E5: 529600 | F5: Оплата на 529,600.00 повторно зачислена в ETM через 23.7 ч, в 1С поступление одно
A6: Повторная оплата | B6: SkyWay Travel | C6: 57419271 | D6: 46206.614 | E6: 410800 | F6: Оплата на 410,800.00 повторно зачислена в ETM через 30.7 ч, в 1С поступление одно
A7: Повторная оплата | B7: ИП Бейшенова Д. О. | C7: 57117017 | D7: 46083.768 | E7: 388600 | F7: Оплата на 388,600.00 повторно зачислена в ETM через 8.1 ч, в 1С поступление одно
A8: Повторная оплата | B8: Сатар уулу Санжар | C8: 57493417 | D8: 46232.703 | E8: 375900 | F8: Оплата на 375,900.00 повторно зачислена в ETM через 29.0 ч, в 1С поступление одно
A9: Повторная оплата | B9: Ак-Куу Авиа | C9: 57070163 | D9: 46056.802 | E9: 365100 | F9: Оплата на 365,100.00 повторно зачислена в ETM через 3.1 ч, в 1С поступление одно
A10: Повторная оплата | B10: ИССЫК ТРИП | C10: 57300423 | D10: 46162.64 | E10: 347500 | F10: Оплата на 347,500.00 повторно зачислена в ETM через 5.7 ч, в 1С поступление одно
A11: Повторная оплата | B11: ЧОЛПОН ЭЙР | C11: 57278297 | D11: 46155.795 | E11: 335700 | F11: Оплата на 335,700.00 повторно зачислена в ETM через 10.0 ч, в 1С поступление одно
A12: Повторная оплата | B12: Абдылда уулу Б. | C12: 57075810 | D12: 46060.68 | E12: 331500 | F12: Оплата на 331,500.00 повторно зачислена в ETM через 23.8 ч, в 1С поступление одно
A13: Повторная оплата | B13: Тянь-Шань Тур | C13: 57433087 | D13: 46210.626 | E13: 288600 | F13: Оплата на 288,600.00 повторно зачислена в ETM через 22.2 ч, в 1С поступление одно
A14: Повторная оплата | B14: Жибек Эйр | C14: 57042021 | D14: 46044.673 | E14: 249400 | F14: Оплата на 249,400.00 повторно зачислена в ETM через 29.7 ч, в 1С поступление одно
A15: Повторная оплата | B15: Ыйык Тур | C15: 57240708 | D15: 46144.368 | E15: 245400 | F15: Оплата на 245,400.00 повторно зачислена в ETM через 21.2 ч, в 1С поступление одно
... A70: Двойное списание | B70: SkyWay Travel | C70: 2460735648 | D70: 46212.416 | E70: -10287 | F70: В ETM 1 лишн. списание(й) одного билета на 10,287.00; без дубля сумма совпадает с 1С

Sheet 1С разрывы между актами
A1: 1С: непрерывность сальдо между актами
A2: Повторяющиеся суммы у разных субагентов (107 557,10; 283 308,99 …) — вопрос бухгалтеру: пакетная корректировка?
A3: Субагент | B3: Период | C3: Конечное сальдо пред. акта | D3: Начальное сальдо акта | E3: Скачок | F3: Тип
A4: ИССЫК ТРИП | B4: 2026-03 | C4: -572828.38 | D4: -2851740.3 | E4: -2278911.9 | F4: Через пропущенный месяц — акт не выгружен
A5: Сатар уулу Санжар | B5: 2026-05 | C5: 202649.34 | D5: -1110441.9 | E5: -1313091.3 | F5: Через пропущенный месяц — акт не выгружен
A6: Чынар уулу Эмир | B6: 2026-04 | C6: -50955.04 | D6: -1242772.6 | E6: -1191817.6 | F6: Через пропущенный месяц — акт не выгружен
A7: ИП Токтосун кызы Н. | B7: 2026-03 | C7: -158891.43 | D7: 828216.58 | E7: 987108.01 | F7: Через пропущенный месяц — акт не выгружен
A8: Жибек Эйр | B8: 2026-06 | C8: -2196501.1 | D8: -1316554.8 | E8: 879946.38 | F8: Через пропущенный месяц — акт не выгружен
A9: Сатар уулу Санжар | B9: 2026-07 | C9: -1806698.6 | D9: -2490873.4 | E9: -684174.86 | F9: Через пропущенный месяц — акт не выгружен
A10: МУРАС ТРИП | B10: 2026-07 | C10: -119011.97 | D10: 475446.34 | E10: 594458.31 | F10: Через пропущенный месяц — акт не выгружен
A11: Жолчу кызы А. | B11: 2026-07 | C11: -534280.46 | D11: -1125552.1 | E11: -591271.65 | F11: Через пропущенный месяц — акт не выгружен
A12: Ak-Bulak Voyage | B12: 2026-03 | C12: -398788.25 | D12: 102299.63 | E12: 501087.88 | F12: Через пропущенный месяц — акт не выгружен
A13: Тянь-Шань Тур | B13: 2026-06 | C13: -181558.58 | D13: -682561.67 | E13: -501003.09 | F13: Через пропущенный месяц — акт не выгружен
A14: ИП Муратов Э. У. | B14: 2026-04 | C14: -1595585.3 | D14: -1902113.1 | E14: -306527.79 | F14: Через пропущенный месяц — акт не выгружен
A15: Жибек Вояж | B15: 2026-05 | C15: -197796.96 | D15: 106851.1 | E15: 304648.06 | F15: Через пропущенный месяц — акт не выгружен
... A42: Sunrise Tours | B42: 2026-06 | C42: -1089093 | D42: -1088830 | E42: 263 | F42: Разрыв (месяцы подряд) — ошибка 1С

Sheet 1С нет актов
A1: Субагент-месяцы без акта 1С (из-за них часть сверки невозможна)
A3: Субагент | B3: Месяц
A4: Ak-Bulak Voyage | B4: 2026-02
A5: Асанов Кубат Чынаревич | B5: 2026-02
A6: Жибек Вояж | B6: 2026-04
A7: Жибек Эйр | B7: 2026-04
A8: Жибек Эйр | B8: 2026-05
A9: Жолчу кызы А. | B9: 2026-06
A10: ИП Асанов К. Б. | B10: 2026-02
A11: ИП Жумабекова Б. Н. | B11: 2026-05
A12: ИП Муратов Э. У. | B12: 2026-03
A13: ИП Токтосун кызы Н. | B13: 2026-02
A14: ИССЫК ТРИП | B14: 2026-02
... A27: Чынар уулу Эмир | B27: 2026-03

Sheet 1С черновик и переиздан
A1: Версии актов: используется последняя (переиздан); ниже — чем версии различаются
A2: Каждая версия по отдельности арифметически сходится; склеивать их нельзя — это и давало ложные «нарушения целостности».
A3: Папка 1С | B3: Период | C3: Сальдо конец (черновик) | D3: Сальдо конец (переиздан) | E3: Разница сальдо | F3: Строк (черновик) | G3: Строк (переиздан) | H3: Только в переизданном | I3: Только в черновике | J3: Проверка арифметики (черновик) | K3: Проверка арифметики (переиздан)
A4: Jailoo Trip | B4: 2026-05 | C4: 703791.61 | D4: 726777.55 | E4: 22985.94 | F4: 14 | G4: 15 | H4: 1 | I4: 0 | J4: -1.1641532e-10 | K4: 0
A5: Tengri Trip | B5: 2026-04 | C5: 586096.79 | D5: 606075.79 | E5: 19979 | F5: 29 | G5: 30 | H5: 1 | I5: 0 | J5: 1.1641532e-10 | K5: 1.1641532e-10
A6: Джолдош уулу Эмир | B6: 2026-02 | C6: -1217910 | D6: -1373610 | E6: -155700 | F6: 21 | G6: 22 | H6: 1 | I6: 0 | J6: -2.3283064e-10 | K6: -2.3283064e-10
A7: ИП Абдылда уулу Б. | B7: 2026-02 | C7: -2377124.5 | D7: -2320420.7 | E7: 56703.81 | F7: 72 | G7: 73 | H7: 1 | I7: 0 | J7: 0 | K7: 0
A8: ИП Абдыраманова Д. А. | B8: 2026-05 | C8: -141203.7 | D8: -140903.7 | E8: 300 | F8: 13 | G8: 14 | H8: 1 | I8: 0 | J8: -2.910383e-11 | K8: -2.910383e-11
A9: ИП Абдыраманова Ж. Д. | B9: 2026-06 | C9: -502180.35 | D9: -489424.35 | E9: 12756 | F9: 17 | G9: 18 | H9: 1 | I9: 0 | J9: 5.8207661e-11 | K9: 5.8207661e-11
A10: ИП Осмонова А. Н. | B10: 2026-04 | C10: -705211.2 | D10: -695320.2 | E10: 9891 | F10: 12 | G10: 13 | H10: 1 | I10: 0 | J10: 0 | K10: 0
A11: Ниязбеков Кубат Таалайевич | B11: 2026-06 | C11: -393972.05 | D11: -343163.93 | E11: 50808.12 | F11: 18 | G11: 19 | H11: 1 | I11: 0 | J11: 0 | K11: 0
A12: ОсОО "Алтын Эйр" | B12: 2026-06 | C12: -1797428.3 | D12: -1754270.3 | E12: 43158 | F12: 35 | G12: 36 | H12: 1 | I12: 0 | J12: 0 | K12: -2.3283064e-10
A13: ОсОО "Иссык Тур" | B13: 2026-06 | C13: -446129.73 | D13: -414876.27 | E13: 31253.46 | F13: 27 | G13: 28 | H13: 1 | I13: 0 | J13: 1.1641532e-10 | K13: 1.1641532e-10
A14: ОсОО "Кок-Жайык Вояж" | B14: 2026-07 | C14: -74298.36 | D14: -55615.31 | E14: 18683.05 | F14: 36 | G14: 37 | H14: 1 | I14: 0 | J14: -1.4551915e-11 | K14: -5.8207661e-11
A15: ОсОО "Манас Тур" | B15: 2026-03 | C15: -980029.12 | D15: -962140.38 | E15: 17888.74 | F15: 13 | G15: 14 | H15: 1 | I15: 0 | J15: 0 | K15: 0
... A18: Эсенбек уулу Азамат | B18: 2026-02 | C18: 200859.12 | D18: 244493.31 | E18: 43634.19 | F18: 9 | G18: 10 | H18: 1 | I18: 0 | J18: 0 | K18: 0

Sheet Сотрудники реестра
A1: Ошибки записи в реестре по сотрудникам (продажи по субагентам)
A2: Различие значимо, только если p-value < 0.05. Если нет — честный вывод: концентрации ошибок по сотруднику в данных нет.
A3: Сотрудник | B3: Ошибок в реестре | C3: Продаж | D3: Доля ошибок | E3: 95% ДИ от | F3: 95% ДИ до | G3: p-value (хи-квадрат) | H3: Различие значимо?
A4: b.isakov | B4: 20 | C4: 1282 | D4: 0.015600624 | E4: 0.010121358 | F4: 0.023974288 | G4: 0.48960908 | H4: FALSE
A5: a.toktosunova | B5: 19 | C5: 1329 | D5: 0.014296464 | E5: 0.0091712945 | F5: 0.022221483 | G5: 0.48960908 | H5: FALSE
A6: g.omurbekova | B6: 15 | C6: 1282 | D6: 0.011700468 | E6: 0.0071032696 | F6: 0.019215369 | G6: 0.48960908 | H6: FALSE
A7: d.mambetova | B7: 15 | C7: 1359 | D7: 0.011037528 | E7: 0.0067001382 | F7: 0.018131508 | G7: 0.48960908 | H7: FALSE
A8: r.sydykov | B8: 14 | C8: 1375 | D8: 0.010181818 | E8: 0.0060746518 | F8: 0.017018356 | G8: 0.48960908 | H8: FALSE
A9: e.satarov | B9: 13 | C9: 1294 | D9: 0.010046368 | E9: 0.00588043 | F9: 0.017112823 | G9: 0.48960908 | H9: FALSE
A10: n.abdyldaeva | B10: 11 | C10: 1327 | D10: 0.0082893745 | E10: 0.0046348573 | F10: 0.01478263 | G10: 0.48960908 | H10: FALSE
A11: k.dzhumaev | B11: 10 | C11: 1334 | D11: 0.0074962519 | E11: 0.0040768317 | F11: 0.013744112 | G11: 0.48960908 | H11: FALSE

Sheet Модель
A1: ML: предупреждающая модель — предсказывает источник проблемы по операции ETM
A2: Метки получены правилами (слабая разметка), признаки известны на момент проводки, проверка строго по времени, дважды. Рядом с метриками — тривиальные baseline. Вывод: модель приоритизирует проверку, а не заменяет правила.
A3: Метрика | B3: main (last month) | C3: check (previous month)
A4: test_month | B4: 2026-07 | C4: 2026-06
A5: train_months | B5: 2026-01..2026-06 | C5: 2026-01..2026-05
A6: n_train | B6: 20067 | C6: 16065
A7: n_test | B7: 4451 | C7: 4002
A8: test_error_rate | B8: 0.065153898 | C8: 0.071464268
A9: accuracy | B9: 0.91889463 | C9: 0.91604198
A10: accuracy_majority_baseline | B10: 0.9348461 | C10: 0.92853573
A11: macro_f1 | B11: 0.2295023 | C11: 0.23673417
A12: macro_f1_majority_baseline | B12: 0.19326521 | C12: 0.19258875
A13: balanced_accuracy | B13: 0.22049423 | C13: 0.22586284
A14: any_error_pr_auc | B14: 0.10264268 | C14: 0.12238104
A15: any_error_pr_auc_baseline_prior_rate | B15: 0.072232017 | C15: 0.075291641
A16: any_error_pr_auc_random | B16: 0.065153898 | C16: 0.071464268
A17: any_error_roc_auc | B17: 0.55877897 | C17: 0.58285283
... A20: recall_at_top5pct | B20: 0.086206897 | C20: 0.090909091
A22: По классам (тест — последний месяц)
A23: class | B23: precision | C23: recall | D23: f1 | E23: support
A24: OK | B24: 0.93643873 | C24: 0.98077385 | D24: 0.95809367 | E24: 4161
A25: BOT | B25: 0.33333333 | C25: 0.083333333 | D25: 0.13333333 | E25: 60
A26: 1C | B26: 0.066666667 | C26: 0.026315789 | D26: 0.037735849 | E26: 114
A27: AGENT | B27: 0 | C27: 0 | D27: 0 | E27: 33
A28: REVIEW | B28: 0.038461538 | C28: 0.012048193 | D28: 0.018348624 | E28: 83
A30: Важность признаков (падение PR-AUC при перемешивании)
A31: feature | B31: pr_auc_drop_when_shuffled
A32: hours_since_same_payment | B32: 0.025557468
A33: kind | B33: 0.01704146
A34: agent_prior_n | B34: 0.005508854
A35: prior_same_ticket_rows | B35: 0.0027737964
A36: hour | B36: 0.0023504794
A37: employee | B37: 0.0018097045
A38: creator | B38: 0.0017313981
A39: weekday | B39: 0.0011145773
A40: n_tickets | B40: 0.0010175246
A41: month_end | B41: -3.1150857e-06
A42: currency | B42: -0.00038613088
A43: dom | B43: -0.0010952312
... A46: agent_prior_err_rate | B46: -0.016029482

Sheet Кейсы для защиты
A1: Три реальных случая: сумма → билет → где потерялось → кто проверяет → что исправить
A3: Кейс 1. Неверная сумма в 1С (подтверждена реестром)
A4: Субагент | B4: Aylana Tour
A5: Сумма и билет | B5: Билет 2461885523: ETM списал 91,284.00, реестр 91,284.00, а в 1С реализация на 19,284.00.
A6: Где потерялось | B6: Реестр и ETM совпадают, 1С одна отличается на 72,000.00 (Реализация AR DJDCDE).
A7: Кто проверяет | B7: Бухгалтер 1С; запись в реестре вёл b.isakov.
A8: Что исправить | B8: Исправить реализацию в 1С на +72,000.00; баланс ETM не трогать.
A10: Кейс 2. Бот списал билет дважды
A11: Субагент | B11: ТАЛАС ЛАЙН
A12: Сумма и билет | B12: Билет 2416946131: в ETM два одинаковых списания, лишнее 62,508.38.
A13: Где потерялось | B13: ETM-операции 57192041,57192059; без дубля сумма ETM = 1С (62,508.38).
A14: Кто проверяет | B14: Разработчик/поддержка бота ETM (защита от повторной проводки); менеджер субагента — возврат списания.
A15: Что исправить | B15: Вернуть на баланс ETM 62,508.38.
A17: Кейс 3. Оплата зачислена в ETM повторно
A18: Субагент | B18: Ak-Bulak Voyage
A19: Сумма и билет | B19: Оплата 562,800.00 от 28.03.2026: в ETM две одинаковые проводки, в 1С поступление одно.
A20: Где потерялось | B20: Оплата на 562,800.00 повторно зачислена в ETM через 21.4 ч, в 1С поступление одно
A21: Кто проверяет | B21: Разработчик/поддержка бота ETM; казначей (подтвердить, что деньги пришли один раз).
A22: Что исправить | B22: Списать с баланса ETM 562,800.00.

Sheet Вопросы бухгалтеру
A1: Конкретные вопросы, которые надо закрыть с бухгалтером
A3: № | B3: Вопрос | C3: Сколько случаев / KGS | D3: Как меняется результат, если ответ «да»
A4: 1 | B4: Сервисный сбор: проводится ли он в 1С отдельной строкой, а в ETM входит в сумму выкупа? Подтвердить, что суммы групп должны совпадать до копейки. | C4: 758 групп с остатком | D4: Группы с остатком, кратным сбору, перейдут из «проверка» в «норма»
A5: 2 | B5: Лаг между проводкой ETM и реализацией 1С: какой допустим (дни)? Операция на границе месяцев — ошибка или перенос? | C5: медиана лага OK-групп 0 дн.; 95-й процентиль 0 дн. | D5: Операции на стыке месяцев исключаются из «нет в 1С» / «акт не выгружен»
A6: 3 | B6: Повторяющиеся суммы разрыва сальдо 1С у разных субагентов (107 557,10; 283 308,99; 4 800; 27 500) — пакетная корректировка/сторно? | C6: 20 разрывов, 2,053,526.35 KGS | D6: Разрыв считается задокументированной корректировкой, а не ошибкой
A7: 4 | B7: Выгрузить недостающие акты 1С по перечню на листе «1С нет актов». | C7: 24 субагент-месяцев | D7: Снимает группы «акт не выгружен» и «скачок через пропуск»
A8: 5 | B8: Кто вводит сумму акта вручную и бывают ли опечатки? Как отличить их от ошибки субагента при самостоятельной выписке (нет записи в реестре)? | C8: 334 групп без третьего источника | D8: Часть «проверка» получит владельца ошибки
A9: 6 | B9: Начальный разрыв на 1 января: есть ли акт сверки/сальдо открытия, которое его объясняет? | C9: 36 субагентов, нетто 2,683,079.59 KGS | D9: Начальный разрыв уйдёт из «выяснить»
A10: 7 | B10: Поступления 1С, по которым в ETM нет оплаты: зачисляются ли такие оплаты на другой договор/в другой период или действительно не доходят на депозит? Номер ЦБ-С… не уникален между субагентами, поэтому как ключ не использован. | C10: 221 поступлений, 60,646,400.00 KGS | D10: Крупнейшая компонента разрыва; ответ определяет, кому её исправлять — боту или казначею

Sheet Допущения и проверки
A1: Допущения, проверки целостности и ограничения
A3: Пункт | B3: Значение / пояснение
A4: Версия акта | B4: Берётся последняя: переиздан > без статуса > черновик. Различия — на листе «1С черновик и переиздан».
A5: Единица сравнения | B5: Связная группа билетов внутри субагента (union-find по билетам ETM, 1С и реестра), а не строка к строке.
A6: Допуск | B6: 5 KGS для ETM↔1С (оба в сомах); 0,5% для реестра в валюте (курс реестра может отличаться).
A7: Баланс ETM | B7: balance_after — сквозной баланс субагента; цепочка проверяется по субагенту; одинаковая секунда — не потеря данных.
